[2024-06-19T09:59:21.711+0000] {local_task_job_runner.py:120} INFO - ::group::Pre task execution logs
[2024-06-19T09:59:21.787+0000] {taskinstance.py:2076} INFO - Dependencies all met for dep_context=non-requeueable deps ti=<TaskInstance: wikipedia_flow.transform_wikipedia_data manual__2024-06-19T09:59:08.733978+00:00 [queued]>
[2024-06-19T09:59:21.809+0000] {taskinstance.py:2076} INFO - Dependencies all met for dep_context=requeueable deps ti=<TaskInstance: wikipedia_flow.transform_wikipedia_data manual__2024-06-19T09:59:08.733978+00:00 [queued]>
[2024-06-19T09:59:21.810+0000] {taskinstance.py:2306} INFO - Starting attempt 1 of 1
[2024-06-19T09:59:21.961+0000] {taskinstance.py:2330} INFO - Executing <Task(PythonOperator): transform_wikipedia_data> on 2024-06-19 09:59:08.733978+00:00
[2024-06-19T09:59:21.976+0000] {standard_task_runner.py:90} INFO - Running: ['***', 'tasks', 'run', 'wikipedia_flow', 'transform_wikipedia_data', 'manual__2024-06-19T09:59:08.733978+00:00', '--job-id', '29', '--raw', '--subdir', 'DAGS_FOLDER/wikipedia_flow.py', '--cfg-path', '/tmp/tmp5vqiphpc']
[2024-06-19T09:59:21.985+0000] {standard_task_runner.py:91} INFO - Job 29: Subtask transform_wikipedia_data
[2024-06-19T09:59:21.989+0000] {logging_mixin.py:188} WARNING - /home/***/.local/lib/python3.12/site-packages/***/task/task_runner/standard_task_runner.py:61 DeprecationWarning: This process (pid=4743) is multi-threaded, use of fork() may lead to deadlocks in the child.
[2024-06-19T09:59:21.991+0000] {standard_task_runner.py:63} INFO - Started process 4745 to run task
[2024-06-19T09:59:22.261+0000] {task_command.py:426} INFO - Running <TaskInstance: wikipedia_flow.transform_wikipedia_data manual__2024-06-19T09:59:08.733978+00:00 [running]> on host dd278de8866b
[2024-06-19T09:59:22.878+0000] {taskinstance.py:2648} INFO - Exporting env vars: AIRFLOW_CTX_DAG_OWNER='Ayush Goswami' AIRFLOW_CTX_DAG_ID='wikipedia_flow' AIRFLOW_CTX_TASK_ID='transform_wikipedia_data' AIRFLOW_CTX_EXECUTION_DATE='2024-06-19T09:59:08.733978+00:00' AIRFLOW_CTX_TRY_NUMBER='1' AIRFLOW_CTX_DAG_RUN_ID='manual__2024-06-19T09:59:08.733978+00:00'
[2024-06-19T09:59:22.880+0000] {taskinstance.py:430} INFO - ::endgroup::
[2024-06-19T10:01:41.529+0000] {connectionpool.py:874} WARNING - Retrying (Retry(total=1, connect=None, read=None, redirect=None, status=None)) after connection broken by 'ReadTimeoutError("HTTPSConnectionPool(host='nominatim.openstreetmap.org', port=443): Read timed out. (read timeout=1)")': /search?q=Stade+du+19-mai-1956%2C%C2%A0Algeria&format=json&limit=1
[2024-06-19T10:02:02.671+0000] {connectionpool.py:874} WARNING - Retrying (Retry(total=1, connect=None, read=None, redirect=None, status=None)) after connection broken by 'ReadTimeoutError("HTTPSConnectionPool(host='nominatim.openstreetmap.org', port=443): Read timed out. (read timeout=1)")': /search?q=Yankee+Stadium%2C%C2%A0United+States&format=json&limit=1
[2024-06-19T10:02:03.686+0000] {connectionpool.py:874} WARNING - Retrying (Retry(total=0, connect=None, read=None, redirect=None, status=None)) after connection broken by 'NewConnectionError('<urllib3.connection.HTTPSConnection object at 0x7f89cceeb5f0>: Failed to establish a new connection: [Errno 101] Network is unreachable')': /search?q=Yankee+Stadium%2C%C2%A0United+States&format=json&limit=1
[2024-06-19T10:02:04.701+0000] {taskinstance.py:441} INFO - ::group::Post task execution logs
[2024-06-19T10:02:04.702+0000] {taskinstance.py:2905} ERROR - Task failed with exception
Traceback (most recent call last):
  File "/home/airflow/.local/lib/python3.12/site-packages/urllib3/connection.py", line 198, in _new_conn
    sock = connection.create_connection(
           ^^^^^^^^^^^^^^^^^^^^^^^^^^^^^
  File "/home/airflow/.local/lib/python3.12/site-packages/urllib3/util/connection.py", line 85, in create_connection
    raise err
  File "/home/airflow/.local/lib/python3.12/site-packages/urllib3/util/connection.py", line 73, in create_connection
    sock.connect(sa)
OSError: [Errno 101] Network is unreachable

The above exception was the direct cause of the following exception:

Traceback (most recent call last):
  File "/home/airflow/.local/lib/python3.12/site-packages/urllib3/connectionpool.py", line 793, in urlopen
    response = self._make_request(
               ^^^^^^^^^^^^^^^^^^^
  File "/home/airflow/.local/lib/python3.12/site-packages/urllib3/connectionpool.py", line 491, in _make_request
    raise new_e
  File "/home/airflow/.local/lib/python3.12/site-packages/urllib3/connectionpool.py", line 467, in _make_request
    self._validate_conn(conn)
  File "/home/airflow/.local/lib/python3.12/site-packages/urllib3/connectionpool.py", line 1099, in _validate_conn
    conn.connect()
  File "/home/airflow/.local/lib/python3.12/site-packages/urllib3/connection.py", line 616, in connect
    self.sock = sock = self._new_conn()
                       ^^^^^^^^^^^^^^^^
  File "/home/airflow/.local/lib/python3.12/site-packages/urllib3/connection.py", line 213, in _new_conn
    raise NewConnectionError(
urllib3.exceptions.NewConnectionError: <urllib3.connection.HTTPSConnection object at 0x7f89cca150d0>: Failed to establish a new connection: [Errno 101] Network is unreachable

The above exception was the direct cause of the following exception:

Traceback (most recent call last):
  File "/home/airflow/.local/lib/python3.12/site-packages/requests/adapters.py", line 486, in send
    resp = conn.urlopen(
           ^^^^^^^^^^^^^
  File "/home/airflow/.local/lib/python3.12/site-packages/urllib3/connectionpool.py", line 877, in urlopen
    return self.urlopen(
           ^^^^^^^^^^^^^
  File "/home/airflow/.local/lib/python3.12/site-packages/urllib3/connectionpool.py", line 877, in urlopen
    return self.urlopen(
           ^^^^^^^^^^^^^
  File "/home/airflow/.local/lib/python3.12/site-packages/urllib3/connectionpool.py", line 847, in urlopen
    retries = retries.increment(
              ^^^^^^^^^^^^^^^^^^
  File "/home/airflow/.local/lib/python3.12/site-packages/urllib3/util/retry.py", line 515, in increment
    raise MaxRetryError(_pool, url, reason) from reason  # type: ignore[arg-type]
    ^^^^^^^^^^^^^^^^^^^^^^^^^^^^^^^^^^^^^^^^^^^^^^^^^^^
urllib3.exceptions.MaxRetryError: HTTPSConnectionPool(host='nominatim.openstreetmap.org', port=443): Max retries exceeded with url: /search?q=Yankee+Stadium%2C%C2%A0United+States&format=json&limit=1 (Caused by NewConnectionError('<urllib3.connection.HTTPSConnection object at 0x7f89cca150d0>: Failed to establish a new connection: [Errno 101] Network is unreachable'))

During handling of the above exception, another exception occurred:

Traceback (most recent call last):
  File "/home/airflow/.local/lib/python3.12/site-packages/geopy/adapters.py", line 482, in _request
    resp = self.session.get(url, timeout=timeout, headers=headers)
           ^^^^^^^^^^^^^^^^^^^^^^^^^^^^^^^^^^^^^^^^^^^^^^^^^^^^^^^
  File "/home/airflow/.local/lib/python3.12/site-packages/requests/sessions.py", line 602, in get
    return self.request("GET", url, **kwargs)
           ^^^^^^^^^^^^^^^^^^^^^^^^^^^^^^^^^^
  File "/home/airflow/.local/lib/python3.12/site-packages/requests/sessions.py", line 589, in request
    resp = self.send(prep, **send_kwargs)
           ^^^^^^^^^^^^^^^^^^^^^^^^^^^^^^
  File "/home/airflow/.local/lib/python3.12/site-packages/requests/sessions.py", line 703, in send
    r = adapter.send(request, **kwargs)
        ^^^^^^^^^^^^^^^^^^^^^^^^^^^^^^^
  File "/home/airflow/.local/lib/python3.12/site-packages/requests/adapters.py", line 519, in send
    raise ConnectionError(e, request=request)
requests.exceptions.ConnectionError: HTTPSConnectionPool(host='nominatim.openstreetmap.org', port=443): Max retries exceeded with url: /search?q=Yankee+Stadium%2C%C2%A0United+States&format=json&limit=1 (Caused by NewConnectionError('<urllib3.connection.HTTPSConnection object at 0x7f89cca150d0>: Failed to establish a new connection: [Errno 101] Network is unreachable'))

During handling of the above exception, another exception occurred:

Traceback (most recent call last):
  File "/home/airflow/.local/lib/python3.12/site-packages/airflow/models/taskinstance.py", line 465, in _execute_task
    result = _execute_callable(context=context, **execute_callable_kwargs)
             ^^^^^^^^^^^^^^^^^^^^^^^^^^^^^^^^^^^^^^^^^^^^^^^^^^^^^^^^^^^^^
  File "/home/airflow/.local/lib/python3.12/site-packages/airflow/models/taskinstance.py", line 432, in _execute_callable
    return execute_callable(context=context, **execute_callable_kwargs)
           ^^^^^^^^^^^^^^^^^^^^^^^^^^^^^^^^^^^^^^^^^^^^^^^^^^^^^^^^^^^^
  File "/home/airflow/.local/lib/python3.12/site-packages/airflow/models/baseoperator.py", line 400, in wrapper
    return func(self, *args, **kwargs)
           ^^^^^^^^^^^^^^^^^^^^^^^^^^^
  File "/home/airflow/.local/lib/python3.12/site-packages/airflow/operators/python.py", line 235, in execute
    return_value = self.execute_callable()
                   ^^^^^^^^^^^^^^^^^^^^^^^
  File "/home/airflow/.local/lib/python3.12/site-packages/airflow/operators/python.py", line 252, in execute_callable
    return self.python_callable(*self.op_args, **self.op_kwargs)
           ^^^^^^^^^^^^^^^^^^^^^^^^^^^^^^^^^^^^^^^^^^^^^^^^^^^^^
  File "/opt/airflow/dags/pipeline/wikipedia_pipeline.py", line 72, in transform_wikipedia_data
    stadium_df['location']=stadium_df.apply(lambda x: get_lat_long(x["country"],x["stadium"]),axis=1)
                           ^^^^^^^^^^^^^^^^^^^^^^^^^^^^^^^^^^^^^^^^^^^^^^^^^^^^^^^^^^^^^^^^^^^^^^^^^^
  File "/home/airflow/.local/lib/python3.12/site-packages/pandas/core/frame.py", line 10034, in apply
    return op.apply().__finalize__(self, method="apply")
           ^^^^^^^^^^
  File "/home/airflow/.local/lib/python3.12/site-packages/pandas/core/apply.py", line 837, in apply
    return self.apply_standard()
           ^^^^^^^^^^^^^^^^^^^^^
  File "/home/airflow/.local/lib/python3.12/site-packages/pandas/core/apply.py", line 965, in apply_standard
    results, res_index = self.apply_series_generator()
                         ^^^^^^^^^^^^^^^^^^^^^^^^^^^^^
  File "/home/airflow/.local/lib/python3.12/site-packages/pandas/core/apply.py", line 981, in apply_series_generator
    results[i] = self.func(v, *self.args, **self.kwargs)
                 ^^^^^^^^^^^^^^^^^^^^^^^^^^^^^^^^^^^^^^^
  File "/opt/airflow/dags/pipeline/wikipedia_pipeline.py", line 72, in <lambda>
    stadium_df['location']=stadium_df.apply(lambda x: get_lat_long(x["country"],x["stadium"]),axis=1)
                                                      ^^^^^^^^^^^^^^^^^^^^^^^^^^^^^^^^^^^^^^^
  File "/opt/airflow/dags/pipeline/wikipedia_pipeline.py", line 61, in get_lat_long
    location = geolocator.geocode(f'{city},{country}')
               ^^^^^^^^^^^^^^^^^^^^^^^^^^^^^^^^^^^^^^^
  File "/home/airflow/.local/lib/python3.12/site-packages/geopy/geocoders/nominatim.py", line 297, in geocode
    return self._call_geocoder(url, callback, timeout=timeout)
           ^^^^^^^^^^^^^^^^^^^^^^^^^^^^^^^^^^^^^^^^^^^^^^^^^^^
  File "/home/airflow/.local/lib/python3.12/site-packages/geopy/geocoders/base.py", line 368, in _call_geocoder
    result = self.adapter.get_json(url, timeout=timeout, headers=req_headers)
             ^^^^^^^^^^^^^^^^^^^^^^^^^^^^^^^^^^^^^^^^^^^^^^^^^^^^^^^^^^^^^^^^
  File "/home/airflow/.local/lib/python3.12/site-packages/geopy/adapters.py", line 472, in get_json
    resp = self._request(url, timeout=timeout, headers=headers)
           ^^^^^^^^^^^^^^^^^^^^^^^^^^^^^^^^^^^^^^^^^^^^^^^^^^^^
  File "/home/airflow/.local/lib/python3.12/site-packages/geopy/adapters.py", line 494, in _request
    raise GeocoderUnavailable(message)
geopy.exc.GeocoderUnavailable: HTTPSConnectionPool(host='nominatim.openstreetmap.org', port=443): Max retries exceeded with url: /search?q=Yankee+Stadium%2C%C2%A0United+States&format=json&limit=1 (Caused by NewConnectionError('<urllib3.connection.HTTPSConnection object at 0x7f89cca150d0>: Failed to establish a new connection: [Errno 101] Network is unreachable'))
[2024-06-19T10:02:04.735+0000] {taskinstance.py:1206} INFO - Marking task as FAILED. dag_id=wikipedia_flow, task_id=transform_wikipedia_data, run_id=manual__2024-06-19T09:59:08.733978+00:00, execution_date=20240619T095908, start_date=20240619T095921, end_date=20240619T100204
[2024-06-19T10:02:04.802+0000] {standard_task_runner.py:110} ERROR - Failed to execute job 29 for task transform_wikipedia_data (HTTPSConnectionPool(host='nominatim.openstreetmap.org', port=443): Max retries exceeded with url: /search?q=Yankee+Stadium%2C%C2%A0United+States&format=json&limit=1 (Caused by NewConnectionError('<urllib3.connection.HTTPSConnection object at 0x7f89cca150d0>: Failed to establish a new connection: [Errno 101] Network is unreachable')); 4745)
[2024-06-19T10:02:04.851+0000] {local_task_job_runner.py:240} INFO - Task exited with return code 1
[2024-06-19T10:02:04.895+0000] {taskinstance.py:3498} INFO - 0 downstream tasks scheduled from follow-on schedule check
[2024-06-19T10:02:04.932+0000] {local_task_job_runner.py:222} INFO - ::endgroup::
