[2024-06-07T08:13:42.482+0000] {task_context_logger.py:104} ERROR - Executor reports task instance <TaskInstance: example_bash_operator.runme_0 scheduled__2024-06-06T00:00:00+00:00 [queued]> finished (failed) although the task says it's queued. (Info: None) Was the task killed externally?
[2024-06-07T08:18:25.853+0000] {task_context_logger.py:104} ERROR - Executor reports task instance <TaskInstance: example_bash_operator.runme_0 scheduled__2024-06-06T00:00:00+00:00 [queued]> finished (failed) although the task says it's queued. (Info: None) Was the task killed externally?
